Workbook

Sheet Dashboard Decisionale
B2: DASHBOARD DECISIONALE | Allocazione Risorse in base al Budget
B3: Inserire il budget disponibile in Parametri!C49 | Dashboard si aggiorna automaticamente | Verde = opzione preferibile | Rosso = non raccomandato nel contesto
B5: iCBT – Indicatori chiave | F5: Collaborative Care – Indicatori chiave
B6: Budget Disponibile (€) | C6: =Parametri!C49 -> 250000 | F6: Budget Disponibile (€) | G6: =Parametri!D49 -> 250000
B7: N Pazienti Trattabili | C7: =FLOOR(Parametri!C49/(Parametri!C26+Parametri!C25),1) -> 528 | F7: N Pazienti Trattabili | G7: =FLOOR(Parametri!D49/(Parametri!D26+Parametri!D25),1) -> 89
B8: Costo per paziente / anno | C8: =Parametri!C26 -> 442.75 | F8: Costo per paziente / anno | G8: =Parametri!D26 -> 2731.25
B9: ROI – 12 mesi | C9: ='ROI 12-24-36 mesi'!C21 -> 5.3725521 | F9: ROI – 12 mesi | G9: ='ROI 12-24-36 mesi'!F21 -> 0.42825996
B10: ROI – 36 mesi | C10: ='ROI 12-24-36 mesi'!C23 -> 5.0223373 | F10: ROI – 36 mesi | G10: ='ROI 12-24-36 mesi'!F23 -> 0.35587186
B11: ICER Anno 1 (€/QALY) | C11: ='Analisi ICER'!C31 -> 162000 | F11: ICER Anno 1 (€/QALY) | G11: N/A (base)
B13: RACCOMANDAZIONE AUTOMATICA DI ALLOCAZIONE RISORSE
B14: Budget disponibile (€) | C14: =Parametri!C49 -> 250000 | F14: Budget disponibile (€) | J14: Modificare in Parametri!C49
B15: N max pazienti con iCBT | C15: =FLOOR(Parametri!C49/(Parametri!C26+Parametri!C25),1) -> 528 | F15: N max pazienti con iCBT | J15: Budget / (Costo ricorrente + Onboarding)
B16: N max pazienti con CollabCare | C16: =FLOOR(Parametri!D49/(Parametri!D26+Parametri!D25),1) -> 89 | F16: N max pazienti con CollabCare | J16: Budget / (Costo ricorrente + Onboarding)
B17: Risparmio per paziente (iCBT vs CC) | C17: =Parametri!D26-Parametri!C26 -> 2288.5 | F17: Risparmio per paziente (iCBT vs CC) | J17: Costo/paz CC − Costo/paz iCBT
B18: Pazienti aggiuntivi con iCBT vs CC | C18: =FLOOR(Parametri!C49/(Parametri!C26+Parametri!C25),1)-FLOOR(Parametri!D49/(Parametri!D26+Parametri!D25),1) -> 439 | F18: Pazienti aggiuntivi con iCBT vs CC | J18: Pazienti extra raggiungibili con iCBT
B19: QALY totali iCBT (Anno 1) | C19: ='Analisi ICER'!C19 -> 7.704 | F19: QALY totali iCBT (Anno 1) | J19: QALY coorte standard (200 paz)
B20: QALY totali CollabCare (Anno 1) | C20: ='Analisi ICER'!D19 -> 10.554 | F20: QALY totali CollabCare (Anno 1) | J20: QALY coorte standard
B21: QALY per € investito – iCBT | C21: =IFERROR('Analisi ICER'!C19/'Analisi ICER'!C10,"N/A") -> 8.1480698e-05 | F21: QALY per € investito – iCBT | J21: Efficienza: QALY / € speso
B22: QALY per € investito – CollabCare | C22: =IFERROR('Analisi ICER'!D19/'Analisi ICER'!D10,"N/A") -> 1.8973483e-05 | F22: QALY per € investito – CollabCare | J22: Efficienza: QALY / € speso
B24: VERDETTO AUTOMATICO – Strategia Consigliata per Budget Disponibile
B25: Strategia consigliata (Budget) | C25: =IF(Parametri!C49<50000,"→ SOLO iCBT: budget limitato, max accesso al costo più basso",IF(Parametri!C49<150000,"→ iCBT prioritario + CC per casi complessi (PHQ-9 ≥15)","→ MODELLO IBRIDO: iCBT lieve-mod / CC moderata-grave – ottimale per copertura e outcome")) -> → MODELLO IBRIDO: iCBT lieve-mod / CC moderata-grave – ottimale per copertura e outcome
B26: Giudizio ICER vs soglia WTP (Anno 1) | C26: ='Analisi ICER'!C37 -> ✗ CC NON cost-effective (Anno 1)
B27: Popolazione target raccomandata per iCBT | C27: ="PHQ-9 5–14 (lieve-moderata): "&TEXT(Parametri!C9*100,"0.0")&"% della coorte" -> PHQ-9 5–14 (lieve-moderata): 65.0% della coorte
B28: Popolazione target raccomandata per CollabCare | C28: ="PHQ-9 ≥15 (moderata-grave): "&TEXT(Parametri!C10*100,"0.0")&"% della coorte" -> PHQ-9 ≥15 (moderata-grave): 35.0% della coorte
B30: CONFRONTO SINTETICO – Dimensioni di Analisi
B31: Dimensione | C31: iCBT | D31: Collaborative Care | E31: Vantaggio
B32: Costo per paziente / anno (€) | C32: =Parametri!C26 -> 442.75 | D32: =Parametri!D26 -> 2731.25 | E32: =IF(Parametri!C26<Parametri!D26,"✓ iCBT","✓ CollabCare") -> ✓ iCBT
B33: Tasso risposta PHQ-9 ≥50% | C33: =Parametri!C30 -> 0.52 | D33: =Parametri!D30 -> 0.61 | E33: =IF(Parametri!C30>Parametri!D30,"✓ iCBT","✓ CollabCare") -> ✓ CollabCare
B34: QALY guadagnati/paziente (Anno 1) | C34: =Parametri!C34*Parametri!C30+Parametri!C35*(1-Parametri!C30) -> 0.03852 | D34: =Parametri!D34*Parametri!D30+Parametri!D35*(1-Parametri!D30) -> 0.05277 | E34: =IF(C32>D32,"✓ iCBT","✓ CollabCare") -> ✓ CollabCare
B35: Pazienti trattabili per €100k budget | C35: =FLOOR(100000/(Parametri!C26+Parametri!C25),1) -> 211 | D35: =FLOOR(100000/(Parametri!D26+Parametri!D25),1) -> 35 | E35: =IF(C33>D33,"✓ iCBT","✓ CollabCare") -> ✓ CollabCare
B36: ROI 36 mesi | C36: ='ROI 12-24-36 mesi'!C23 -> 5.0223373 | D36: ='ROI 12-24-36 mesi'!F23 -> 0.35587186 | E36: =IF(C34>D34,"✓ iCBT","✓ CollabCare") -> ✓ CollabCare
B37: ICER vs soglia €30.000/QALY | C37: =IF('Analisi ICER'!C31<30000,"✓ Sotto soglia","✗ Sopra soglia") -> ✗ Sopra soglia | D37: "Base (confronto)" | E37: "→ Vedere foglio ICER"
B38: Scalabilità digitale | C38: "Alta (SaaS, async)" | D38: "Bassa (staff-dipendente)" | E38: "✓ iCBT"
B39: Adatto a casi complessi | C39: "No (lieve-mod)" | D39: "Sì (mod-grave)" | E39: "✓ CollabCare"
B40: Drop-out / Abbandono | C40: =Parametri!C33 -> 0.22 | D40: =Parametri!D33 -> 0.18 | E40: =IF(Parametri!C33<Parametri!D33,"✓ iCBT","✓ CollabCare") -> ✓ CollabCare
B42: Fonti: Johansson et al. 2019 (J Affect Disord); Chisholm et al. 2016 (Lancet Psychiatry); Nordgreen et al. 2021 (JMIR); Bower et al. 2006 (BMJ); EuroQol EQ-5D; NICE TA NHS 2023. Modello creato per analisi HTA – tutti i parametri sono modificabili nel foglio Parametri.

Sheet Parametri
B2: ANALISI COSTO-UTILITÀ | iCBT vs Collaborative Care | G2: 26
B3: Foglio Parametri – Valori modificabili (blu) | Formule (nero) | Link inter-foglio (verde) | G3: 34
B4: ● Blu = Input modificabile | C4: ● Nero = Formula calcolata | D4: ● Verde = Link inter-foglio | E4: ● Giallo = Assunzione chiave | G4: 35
G5: 30
B6: A | POPOLAZIONE & CONTESTO CLINICO | G6: 38
B7: Parametro | C7: iCBT | D7: Collaborative Care | E7: Unità / Note | G7: 39
B8: Pazienti per coorte (N) | C8: 200 | D8: 200 | E8: n – modificabile | G8: 43
B9: % Depressione lieve-moderata (PHQ-9 5–14) | C9: 0.65 | D9: 0.6 | E9: proporzione | G9: 44
B10: % Depressione moderata-grave (PHQ-9 ≥15) | C10: 0.35 | D10: 0.4 | E10: proporzione | G10: 49
B11: Età media pazienti (anni) | C11: 42 | D11: 42 | E11: anni | G11: 46
B12: % Pazienti occupati | C12: 0.68 | D12: 0.68 | E12: proporzione | G12: 47
B13: Orizzonte temporale primario | C13: 1 | D13: 1 | E13: anni (1 = 12 mesi) | G13: 48
G14: 25
B15: B | COSTI DIRETTI (€ per paziente / anno) – Fonte: letteratura HTA europea
B16: Parametro | C16: iCBT | D16: Collaborative Care | E16: Unità / Note
B17: Costo piattaforma / licenza software | C17: 120 | D17: 0 | E17: €/paz – iCBT: SaaS annuo
B18: Costo terapeuta / clinico (ore × tariffa) | C18: 80 | D18: 1200 | E18: €/paz – iCBT: email/supporto async
B19: Costo supervisore / care manager | C19: 0 | D19: 420 | E19: €/paz – CC: care manager dedicato
B20: Costo medico di base (MMG) / contatti | C20: 60 | D20: 240 | E20: €/paz – visite e-mail vs. in presenza
B21: Costo psichiatra / specialista | C21: 0 | D21: 360 | E21: €/paz – CC: consulenze periodiche
B22: Costo farmaci antidepressivi | C22: 80 | D22: 120 | E22: €/paz – SSRI generico vs brand
B23: Costo ricoveri / pronto soccorso | C23: 45 | D23: 35 | E23: €/paz – tasso stimato da letteratura
B24: Costo amministrativo / overhead (15% su precedenti) | C24: =SUM(C17:C23)*0.15 -> 57.75 | D24: =SUM(D17:D23)*0.15 -> 356.25 | E24: formula automatica – 15% subtotale
B25: Costo induzione / onboarding paziente (anno 1 only) | C25: 30 | D25: 50 | E25: ⚠ Una-tantum – incluso solo in Anno 1
B26: TOTALE COSTI DIRETTI / paziente (senza onboarding) | C26: =SUM(C17:C24) -> 442.75 | D26: =SUM(D17:D24) -> 2731.25 | E26: Costo ricorrente annuo per paziente
B28: C | EFFICACIA CLINICA – PHQ-9 & QALY (Fonte: Johansson 2019; Chisholm 2016; Nordgreen 2021)
B29: Parametro | C29: iCBT | D29: Collaborative Care | E29: Unità / Note
B30: Tasso risposta (riduzione PHQ-9 ≥50%) | C30: 0.52 | D30: 0.61 | E30: proporzione – da RCT
B31: Tasso remissione (PHQ-9 <5) | C31: 0.38 | D31: 0.45 | E31: proporzione – da RCT
B32: Variazione media PHQ-9 (pre→post) | C32: -5.8 | D32: -6.9 | E32: punti PHQ-9 (negativo = miglioramento)
B33: Drop-out / abbandono trattamento | C33: 0.22 | D33: 0.18 | E33: proporzione
B34: QALY guadagnati – responder (anno 1) | C34: 0.063 | D34: 0.075 | E34: QALY – da utility mapping EQ-5D
B35: QALY guadagnati – non-responder (anno 1) | C35: 0.012 | D35: 0.018 | E35: QALY – beneficio residuo
B36: Utility baseline (PHQ-9 lieve-mod) | C36: 0.68 | D36: 0.68 | E36: utility EQ-5D pre-trattamento
B37: Utility post-trattamento responder | C37: 0.81 | D37: 0.84 | E37: utility EQ-5D post-trattamento
B38: Mantenimento effetto – Anno 2 (decay) | C38: 0.75 | D38: 0.82 | E38: proporzione QALY mantenuto vs anno 1
B39: Mantenimento effetto – Anno 3 (decay) | C39: 0.6 | D39: 0.7 | E39: proporzione QALY mantenuto vs anno 1
B41: D | PARAMETRI ECONOMICI
B42: Parametro | C42: iCBT | D42: Collaborative Care | E42: Unità / Note
B43: Soglia WTP per QALY (€) | C43: 30000 | D43: 30000 | E43: € – threshold NHS/SSN europeo
...

Sheet Analisi ICER
B2: ANALISI COSTO-EFFICACIA INCREMENTALE (ICER) | iCBT vs Collaborative Care
B3: ICER = (Costo_CC – Costo_iCBT) / (QALY_CC – QALY_iCBT) | Soglia WTP: da Parametri!C43
B5: Componente di Analisi | C5: iCBT | D5: Collaborative Care | E5: Differenza (CC – iCBT) | F5: Note / Interpretazione
B6: A | COSTI TOTALI PER COORTE (Anno 1, N pazienti da Parametri!C8)
B7: Pazienti in coorte (N) | C7: =Parametri!C8 -> 200 | D7: =Parametri!D8 -> 200 | E7: =D7-C7 -> 0 | F7: Da Parametri foglio
B8: Costo ricorrente/paziente (€) | C8: =Parametri!C26 -> 442.75 | D8: =Parametri!D26 -> 2731.25 | E8: =D8-C8 -> 2288.5 | F8: Comprende tutti i costi diretti
B9: Costo onboarding/paziente (anno 1, €) | C9: =Parametri!C25 -> 30 | D9: =Parametri!D25 -> 50 | E9: =D9-C9 -> 20 | F9: Una-tantum – solo Anno 1
B10: COSTO TOTALE COORTE Anno 1 (€) | C10: =C7*(C8+C9) -> 94550 | D10: =D7*(D8+D9) -> 556250 | E10: =D10-C10 -> 461700 | F10: Costo × N pazienti
B11: COSTO TOTALE COORTE Anno 2 (€, senza onboarding) | C11: =C7*C8*(1+Parametri!C45) -> 90763.75 | D11: =D7*D8*(1+Parametri!D45) -> 559906.25 | E11: =D11-C11 -> 469142.5 | F11: Con tasso inflazione sanitaria
B12: COSTO TOTALE COORTE Anno 3 (€) | C12: =C7*C8*(1+Parametri!C45)^2 -> 93032.844 | D12: =D7*D8*(1+Parametri!D45)^2 -> 573903.91 | E12: =D12-C12 -> 480871.06 | F12: Composto per 2 anni inflazione
B14: B | EFFETTI IN QALY PER COORTE (da Parametri, utilità EQ-5D)
B15: Responder (N pazienti) | C15: =ROUND(Parametri!C8*Parametri!C30,0) -> 104 | D15: =ROUND(Parametri!D8*Parametri!D30,0) -> 122 | E15: =D15-C15 -> 18 | F15: N × tasso risposta PHQ-9
B16: Non-responder (N pazienti) | C16: =Parametri!C8-C15 -> 96 | D16: =Parametri!D8-D15 -> 78 | E16: =D16-C16 -> -18 | F16: Pazienti totali − responder
B17: QALY guadagnati – responder (Anno 1) | C17: =C15*Parametri!C34 -> 6.552 | D17: =D15*Parametri!D34 -> 9.15 | E17: =D17-C17 -> 2.598 | F17: N responder × QALY unitario (EQ-5D)
B18: QALY guadagnati – non-responder (Anno 1) | C18: =C16*Parametri!C35 -> 1.152 | D18: =D16*Parametri!D35 -> 1.404 | E18: =D18-C18 -> 0.252 | F18: N non-resp × QALY residuo
B19: QALY TOTALI COORTE – Anno 1 | C19: =C17+C18 -> 7.704 | D19: =D17+D18 -> 10.554 | E19: =D19-C19 -> 2.85 | F19: Somma responder + non-responder
B20: QALY TOTALI COORTE – Anno 2 (mantenimento decay) | C20: =C19*Parametri!C38 -> 5.778 | D20: =D19*Parametri!D38 -> 8.65428 | E20: =D20-C20 -> 2.87628 | F20: Anno 1 × fattore decay Parametri
B21: QALY TOTALI COORTE – Anno 3 (mantenimento decay) | C21: =C19*Parametri!C39 -> 4.6224 | D21: =D19*Parametri!D39 -> 7.3878 | E21: =D21-C21 -> 2.7654 | F21: Anno 1 × fattore decay Parametri
B23: C | CALCOLO ICER (Incremental Cost-Effectiveness Ratio)
B24: ΔCosto (CC − iCBT) – Anno 1 (€) | C24: =D10-C10 -> 461700 | F24: Δ = Collaborative Care − iCBT
B25: ΔCosto (CC − iCBT) – Anno 2 (€) | C25: =D11-C11 -> 469142.5 | F25: Δ = Collaborative Care − iCBT
B26: ΔCosto (CC − iCBT) – Anno 3 (€) | C26: =D12-C12 -> 480871.06 | F26: Δ = Collaborative Care − iCBT
B27: ΔQALY (CC − iCBT) – Anno 1 | C27: =D19-C19 -> 2.85 | F27: Δ = Collaborative Care − iCBT
B28: ΔQALY (CC − iCBT) – Anno 2 | C28: =D20-C20 -> 2.87628 | F28: Δ = Collaborative Care − iCBT
B29: ΔQALY (CC − iCBT) – Anno 3 | C29: =D21-C21 -> 2.7654 | F29: Δ = Collaborative Care − iCBT
B31: ICER per QALY – Anno 1 (€/QALY) | C31: =IFERROR(C24/C27,"N/A – ΔQALY=0") -> 162000 | F31: ICER < soglia WTP → CC cost-effective vs iCBT
B32: ICER per QALY – Anno 2 (€/QALY) | C32: =IFERROR((C24+C25)/(C27+C28),"N/A") -> 162556.23 | F32: ICER cumulativo 2 anni
B33: ICER per QALY – Anno 3 (€/QALY) | C33: =IFERROR((C24+C25+C26)/(C27+C28+C29),"N/A") -> 166246.67 | F33: ICER cumulativo 3 anni
B35: D | GIUDIZIO AUTOMATICO DI COST-EFFECTIVENESS (vs soglia WTP)
B36: Soglia WTP (€/QALY) da Parametri | C36: =Parametri!C43 -> 30000 | F36: Threshold SSN europeo – modificabile
B37: Giudizio ICER Anno 1 | C37: =IF(ISNUMBER(C31),IF(C31<Parametri!C43,"✓ CC COST-EFFECTIVE (Anno 1)",IF(C31>0,"✗ CC NON cost-effective (Anno 1)","✓ iCBT DOMINA (più economico e migliore)")),"→ iCBT domina") -> ✗ CC NON cost-effective (Anno 1) | F37: Confronto ICER vs soglia WTP
B38: Giudizio ICER Anno 2 | C38: =IF(ISNUMBER(C32),IF(C32<Parametri!C43,"✓ CC COST-EFFECTIVE (Anno 2)",IF(C32>0,"✗ CC NON cost-effective (Anno 2)","✓ iCBT DOMINA")),"→ iCBT domina") -> ✗ CC NON cost-effective (Anno 2) | F38: ICER cumulativo 2 anni
B39: Giudizio ICER Anno 3 | C39: =IF(ISNUMBER(C33),IF(C33<Parametri!C43,"✓ CC COST-EFFECTIVE (Anno 3)",IF(C33>0,"✗ CC NON cost-effective (Anno 3)","✓ iCBT DOMINA")),"→ iCBT domina") -> ✗ CC NON cost-effective (Anno 3) | F39: ICER cumulativo 3 anni

Sheet ROI 12-24-36 mesi
B2: ANALISI ROI | iCBT vs Collaborative Care | Orizzonte 12 – 24 – 36 mesi
B3: ROI = (Benefici Totali – Costi Totali) / Costi Totali | Include benefici clinici + risparmio assenteismo
B5: Componente ROI | C5: iCBT Anno 1 | D5: iCBT Anno 2 | E5: iCBT Anno 3 | F5: CollabCare Anno 1 | G5: CollabCare Anno 2 | H5: CollabCare Anno 3 | I5: Diff Anno 1 (CC−iCBT, €) | J5: Diff Anno 3 (CC−iCBT, €)
B6: A | INVESTIMENTI (COSTI TOTALI, €)
B7: Costi totali – Anno 1 (€) | C7: ='Analisi ICER'!C10 -> 94550 | D7: ='Analisi ICER'!C11 -> 90763.75 | E7: ='Analisi ICER'!C12 -> 93032.844 | F7: ='Analisi ICER'!D10 -> 556250 | G7: ='Analisi ICER'!D11 -> 559906.25 | H7: ='Analisi ICER'!D12 -> 573903.91 | I7: =F7-C7 -> 461700 | J7: =H7-E7 -> 480871.06
B8: Costi cumulativi 12 mesi (€) | C8: =C7 -> 94550 | D8: N/A | E8: 0 | F8: =F7 -> 556250 | G8: N/A | H8: 0 | I8: =F8-C8 -> 461700 | J8: =IFERROR(H8-E8,0) -> 0
B9: Costi cumulativi 24 mesi (€) | C9: =C7 -> 94550 | D9: =C7+D7 -> 185313.75 | E9: 0 | F9: =F7 -> 556250 | G9: =F7+G7 -> 1116156.2 | H9: 0 | I9: =F9-C9 -> 461700 | J9: =IFERROR(H9-E9,0) -> 0
B10: Costi cumulativi 36 mesi (€) | C10: =C7 -> 94550 | D10: =C7+D7 -> 185313.75 | E10: =C7+D7+E7 -> 278346.59 | F10: =F7 -> 556250 | G10: =F7+G7 -> 1116156.2 | H10: =F7+G7+H7 -> 1690060.2 | I10: =F10-C10 -> 461700 | J10: =H10-E10 -> 1411713.6
B12: B | BENEFICI TOTALI (Clinici + Risparmio Assenteismo, €)
B13: Beneficio clinico QALY monetiz. – Anno 1 (€) | C13: ='Analisi ICER'!C19*Parametri!C43 -> 231120 | D13: ='Analisi ICER'!C20*Parametri!C43 -> 173340 | E13: ='Analisi ICER'!C21*Parametri!C43 -> 138672 | F13: ='Analisi ICER'!D19*Parametri!D43 -> 316620 | G13: ='Analisi ICER'!D20*Parametri!D43 -> 259628.4 | H13: ='Analisi ICER'!D21*Parametri!D43 -> 221634 | I13: =F13-C13 -> 85500 | J13: =H13-E13 -> 82962
B14: Risparmio assenteismo responder – Anno 1 (€) | C14: =ROUND(Parametri!C8*Parametri!C30,0)*Parametri!C47*Parametri!C46*Parametri!C48 -> 371404.8 | D14: =ROUND(Parametri!C8*Parametri!C30,0)*Parametri!C47*Parametri!C46*Parametri!C48*(1+Parametri!C45) -> 380689.92 | E14: =ROUND(Parametri!C8*Parametri!C30,0)*Parametri!C47*Parametri!C46*Parametri!C48*(1+Parametri!C45)^2 -> 390207.17 | F14: =ROUND(Parametri!D8*Parametri!D30,0)*Parametri!D47*Parametri!D46*Parametri!D48 -> 477849.6 | G14: =ROUND(Parametri!D8*Parametri!D30,0)*Parametri!D47*Parametri!D46*Parametri!D48*(1+Parametri!D45) -> 489795.84 | H14: =ROUND(Parametri!D8*Parametri!D30,0)*Parametri!D47*Parametri!D46*Parametri!D48*(1+Parametri!D45)^2 -> 502040.74 | I14: =F14-C14 -> 106444.8 | J14: =H14-E14 -> 111833.57
B15: TOTALE BENEFICI – per anno (€) | C15: =SUM(C13:C14) -> 602524.8 | D15: =SUM(D13:D14) -> 554029.92 | E15: =SUM(E13:E14) -> 528879.17 | F15: =SUM(F13:F14) -> 794469.6 | G15: =SUM(G13:G14) -> 749424.24 | H15: =SUM(H13:H14) -> 723674.74 | I15: =F15-C15 -> 191944.8 | J15: =H15-E15 -> 194795.57
B17: C | ROI CALCOLATO = (Benefici – Costi) / Costi
B18: Net Benefit – 12 mesi (€) | C18: =C15-C7 -> 507974.8 | F18: =F15-F7 -> 238219.6 | I18: =F18-C18 -> -269755.2 | J18: =H18-E18 -> 0
B19: Net Benefit – 24 mesi (€) | C19: =IFERROR((C15+D15)-(C8+D8),"N/A") -> N/A | F19: =IFERROR((F15+G15)-(F8+G8),"N/A") -> N/A | I19: =IFERROR(F19-C19,"N/A") -> N/A | J19: =H19-E19 -> 0
B20: Net Benefit – 36 mesi (€) | C20: =IFERROR((C15+D15+E15)-(C9+D9+E9),"N/A") -> 1405570.1 | F20: =IFERROR((F15+G15+H15)-(F9+G9+H9),"N/A") -> 595162.33 | I20: =IFERROR(F20-C20,"N/A") -> -810407.81 | J20: =H20-E20 -> 0
B21: ROI – 12 mesi (%) | C21: =IFERROR((C15-C7)/C7,"N/A") -> 5.3725521 | F21: =IFERROR((F15-F7)/F7,"N/A") -> 0.42825996 | I21: =F21-C21 -> -4.9442921 | J21: =H21-E21 -> 0
B22: ROI – 24 mesi (%) | C22: =IFERROR(((C15+D15)-(C8+D8))/(C8+D8),"N/A") -> N/A | F22: =IFERROR(((F15+G15)-(F8+G8))/(F8+G8),"N/A") -> N/A | I22: =IFERROR(F22-C22,"N/A") -> N/A | J22: =H22-E22 -> 0
B23: ROI – 36 mesi (%) | C23: =IFERROR(((C15+D15+E15)-(C9+D9+E9))/(C9+D9+E9),"N/A") -> 5.0223373 | F23: =IFERROR(((F15+G15+H15)-(F9+G9+H9))/(F9+G9+H9),"N/A") -> 0.35587186 | I23: =IFERROR(F23-C23,"N/A") -> -4.6664654 | J23: =H23-E23 -> 0
B24: Payback period stimato – iCBT | C24: =IFERROR(C7/(C15/12),"N/A") -> 1.883076 | F24: =IFERROR(F7/(F15/12),"N/A") -> 8.4018319 | I24: =F24-C24 -> 6.5187558 | J24: =H24-E24 -> 0

Sheet Analisi Sensibilità
B2: ANALISI DI SENSIBILITÀ | Variazione Parametri chiave su ICER e ROI
B3: Ogni parametro viene variato ±20% e ±40% rispetto al valore base (ceteris paribus). I valori base provengono dal foglio Parametri.
B5: A | SENSIBILITÀ UNIVARIATA SU ICER (€/QALY, Anno 1) – Variazione ±20% / ±40% dal valore base
B6: Parametro | C6: Valore Base | D6: −40% ICER (€/QALY) | E6: −20% ICER (€/QALY) | F6: Base ICER (€/QALY) | G6: +20% ICER (€/QALY) | H6: +40% ICER (€/QALY) | I6: Range ICER (max−min)
B7: Costo ricorrente/paz iCBT (€) | C7: =Parametri!C26 -> 442.75 | D7: =IFERROR(((Parametri!D8*1)*(Parametri!D26*1+Parametri!D25)-(Parametri!C8*1)*(Parametri!C26*0.6+Parametri!C25))/((Parametri!D8*1)*(ROUND((Parametri!D8*1)*(Parametri!D30*1)/(Parametri!D8*1),0)*(Parametri!D34*1)+(ROUND((Parametri!D8*1),0)-ROUND((Parametri!D8*1)*(Parametri!D30*1),0))*(Parametri!D35))-(Parametri!C8*1)*(ROUND((Parametri!C8*1)*(Parametri!C30*1)/(Parametri!C8*1),0)*(Parametri!C34*1)+(ROUND((Parametri!C8*1),0)-ROUND((Parametri!C8*1)*(Parametri!C30*1),0))*(Parametri!C35))),"N/A") -> 9415.1515 | E7: =IFERROR(((Parametri!D8*1)*(Parametri!D26*1+Parametri!D25)-(Parametri!C8*1)*(Parametri!C26*0.8+Parametri!C25))/((Parametri!D8*1)*(ROUND((Parametri!D8*1)*(Parametri!D30*1)/(Parametri!D8*1),0)*(Parametri!D34*1)+(ROUND((Parametri!D8*1),0)-ROUND((Parametri!D8*1)*(Parametri!D30*1),0))*(Parametri!D35))-(Parametri!C8*1)*(ROUND((Parametri!C8*1)*(Parametri!C30*1)/(Parametri!C8*1),0)*(Parametri!C34*1)+(ROUND((Parametri!C8*1),0)-ROUND((Parametri!C8*1)*(Parametri!C30*1),0))*(Parametri!C35))),"N/A") -> 9079.7348 | F7: =IFERROR(((Parametri!D8*1)*(Parametri!D26*1+Parametri!D25)-(Parametri!C8*1)*(Parametri!C26*1+Parametri!C25))/((Parametri!D8*1)*(ROUND((Parametri!D8*1)*(Parametri!D30*1)/(Parametri!D8*1),0)*(Parametri!D34*1)+(ROUND((Parametri!D8*1),0)-ROUND((Parametri!D8*1)*(Parametri!D30*1),0))*(Parametri!D35))-(Parametri!C8*1)*(ROUND((Parametri!C8*1)*(Parametri!C30*1)/(Parametri!C8*1),0)*(Parametri!C34*1)+(ROUND((Parametri!C8*1),0)-ROUND((Parametri!C8*1)*(Parametri!C30*1),0))*(Parametri!C35))),"N/A") -> 8744.3182 | G7: =IFERROR(((Parametri!D8*1)*(Parametri!D26*1+Parametri!D25)-(Parametri!C8*1)*(Parametri!C26*1.2+Parametri!C25))/((Parametri!D8*1)*(ROUND((Parametri!D8*1)*(Parametri!D30*1)/(Parametri!D8*1),0)*(Parametri!D34*1)+(ROUND((Parametri!D8*1),0)-ROUND((Parametri!D8*1)*(Parametri!D30*1),0))*(Parametri!D35))-(Parametri!C8*1)*(ROUND((Parametri!C8*1)*(Parametri!C30*1)/(Parametri!C8*1),0)*(Parametri!C34*1)+(ROUND((Parametri!C8*1),0)-ROUND((Parametri!C8*1)*(Parametri!C30*1),0))*(Parametri!C35))),"N/A") -> 8408.9015 | H7: =IFERROR(((Parametri!D8*1)*(Parametri!D26*1+Parametri!D25)-(Parametri!C8*1)*(Parametri!C26*1.4+Parametri!C25))/((Parametri!D8*1)*(ROUND((Parametri!D8*1)*(Parametri!D30*1)/(Parametri!D8*1),0)*(Parametri!D34*1)+(ROUND((Parametri!D8*1),0)-ROUND((Parametri!D8*1)*(Parametri!D30*1),0))*(Parametri!D35))-(Parametri!C8*1)*(ROUND((Parametri!C8*1)*(Parametri!C30*1)/(Parametri!C8*1),0)*(Parametri!C34*1)+(ROUND((Parametri!C8*1),0)-ROUND((Parametri!C8*1)*(Parametri!C30*1),0))*(Parametri!C35))),"N/A") -> 8073.4848 | I7: =IFERROR(MAX(D7:H7)-MIN(D7:H7),"N/A") -> 1341.6667
B8: Costo ricorrente/paz CollabCare (€) | C8: =Parametri!D26 -> 2731.25 | D8: =IFERROR(((Parametri!D8*1)*(Parametri!D26*0.6+Parametri!D25)-(Parametri!C8*1)*(Parametri!C26*1+Parametri!C25))/((Parametri!D8*1)*(ROUND((Parametri!D8*1)*(Parametri!D30*1)/(Parametri!D8*1),0)*(Parametri!D34*1)+(ROUND((Parametri!D8*1),0)-ROUND((Parametri!D8*1)*(Parametri!D30*1),0))*(Parametri!D35))-(Parametri!C8*1)*(ROUND((Parametri!C8*1)*(Parametri!C30*1)/(Parametri!C8*1),0)*(Parametri!C34*1)+(ROUND((Parametri!C8*1),0)-ROUND((Parametri!C8*1)*(Parametri!C30*1),0))*(Parametri!C35))),"N/A") -> 4606.0606 | E8: =IFERROR(((Parametri!D8*1)*(Parametri!D26*0.8+Parametri!D25)-(Parametri!C8*1)*(Parametri!C26*1+Parametri!C25))/((Parametri!D8*1)*(ROUND((Parametri!D8*1)*(Parametri!D30*1)/(Parametri!D8*1),0)*(Parametri!D34*1)+(ROUND((Parametri!D8*1),0)-ROUND((Parametri!D8*1)*(Parametri!D30*1),0))*(Parametri!D35))-(Parametri!C8*1)*(ROUND((Parametri!C8*1)*(Parametri!C30*1)/(Parametri!C8*1),0)*(Parametri!C34*1)+(ROUND((Parametri!C8*1),0)-ROUND((Parametri!C8*1)*(Parametri!C30*1),0))*(Parametri!C35))),"N/A") -> 6675.1894 | F8: =IFERROR(((Parametri!D8*1)*(Parametri!D26*1+Parametri!D25)-(Parametri!C8*1)*(Parametri!C26*1+Parametri!C25))/((Parametri!D8*1)*(ROUND((Parametri!D8*1)*(Parametri!D30*1)/(Parametri!D8*1),0)*(Parametri!D34*1)+(ROUND((Parametri!D8*1),0)-ROUND((Parametri!D8*1)*(Parametri!D30*1),0))*(Parametri!D35))-(Parametri!C8*1)*(ROUND((Parametri!C8*1)*(Parametri!C30*1)/(Parametri!C8*1),0)*(Parametri!C34*1)+(ROUND((Parametri!C8*1),0)-ROUND((Parametri!C8*1)*(Parametri!C30*1),0))*(Parametri!C35))),"N/A") -> 8744.3182 | G8: =IFERROR(((Parametri!D8*1)*(Parametri!D26*1.2+Parametri!D25)-(Parametri!C8*1)*(Parametri!C26*1+Parametri!C25))/((Parametri!D8*1)*(ROUND((Parametri!D8*1)*(Parametri!D30*1)/(Parametri!D8*1),0)*(Parametri!D34*1)+(ROUND((Parametri!D8*1),0)-ROUND((Parametri!D8*1)*(Parametri!D30*1),0))*(Parametri!D35))-(Parametri!C8*1)*(ROUND((Parametri!C8*1)*(Parametri!C30*1)/(Parametri!C8*1),0)*(Parametri!C34*1)+(ROUND((Parametri!C8*1),0)-ROUND((Parametri!C8*1)*(Parametri!C30*1),0))*(Parametri!C35))),"N/A") -> 10813.447 | H8: =IFERROR(((Parametri!D8*1)*(Parametri!D26*1.4+Parametri!D25)-(Parametri!C8*1)*(Parametri!C26*1+Parametri!C25))/((Parametri!D8*1)*(ROUND((Parametri!D8*1)*(Parametri!D30*1)/(Parametri!D8*1),0)*(Parametri!D34*1)+(ROUND((Parametri!D8*1),0)-ROUND((Parametri!D8*1)*(Parametri!D30*1),0))*(Parametri!D35))-(Parametri!C8*1)*(ROUND((Parametri!C8*1)*(Parametri!C30*1)/(Parametri!C8*1),0)*(Parametri!C34*1)+(ROUND((Parametri!C8*1),0)-ROUND((Parametri!C8*1)*(Parametri!C30*1),0))*(Parametri!C35))),"N/A") -> 12882.576 | I8: =IFERROR(MAX(D8:H8)-MIN(D8:H8),"N/A") -> 8276.5152
B9: Tasso risposta iCBT (PHQ-9 ≥50%) | C9: =Parametri!C30 -> 0.52 | D9: =IFERROR(((Parametri!D8*1)*(Parametri!D26*1+Parametri!D25)-(Parametri!C8*1)*(Parametri!C26*1+Parametri!C25))/((Parametri!D8*1)*(ROUND((Parametri!D8*1)*(Parametri!D30*1)/(Parametri!D8*1),0)*(Parametri!D34*1)+(ROUND((Parametri!D8*1),0)-ROUND((Parametri!D8*1)*(Parametri!D30*1),0))*(Parametri!D35))-(Parametri!C8*1)*(ROUND((Parametri!C8*1)*(Parametri!C30*0.6)/(Parametri!C8*1),0)*(Parametri!C34*1)+(ROUND((Parametri!C8*1),0)-ROUND((Parametri!C8*1)*(Parametri!C30*0.6),0))*(Parametri!C35))),"N/A") -> -13042.373 | E9: =IFERROR(((Parametri!D8*1)*(Parametri!D26*1+Parametri!D25)-(Parametri!C8*1)*(Parametri!C26*1+Parametri!C25))/((Parametri!D8*1)*(ROUND((Parametri!D8*1)*(Parametri!D30*1)/(Parametri!D8*1),0)*(Parametri!D34*1)+(ROUND((Parametri!D8*1),0)-ROUND((Parametri!D8*1)*(Parametri!D30*1),0))*(Parametri!D35))-(Parametri!C8*1)*(ROUND((Parametri!C8*1)*(Parametri!C30*0.8)/(Parametri!C8*1),0)*(Parametri!C34*1)+(ROUND((Parametri!C8*1),0)-ROUND((Parametri!C8*1)*(Parametri!C30*0.8),0))*(Parametri!C35))),"N/A") -> 30780 | F9: =IFERROR(((Parametri!D8*1)*(Parametri!D26*1+Parametri!D25)-(Parametri!C8*1)*(Parametri!C26*1+Parametri!C25))/((Parametri!D8*1)*(ROUND((Parametri!D8*1)*(Parametri!D30*1)/(Parametri!D8*1),0)*(Parametri!D34*1)+(ROUND((Parametri!D8*1),0)-ROUND((Parametri!D8*1)*(Parametri!D30*1),0))*(Parametri!D35))-(Parametri!C8*1)*(ROUND((Parametri!C8*1)*(Parametri!C30*1)/(Parametri!C8*1),0)*(Parametri!C34*1)+(ROUND((Parametri!C8*1),0)-ROUND((Parametri!C8*1)*(Parametri!C30*1),0))*(Parametri!C35))),"N/A") -> 8744.3182 | G9: =IFERROR(((Parametri!D8*1)*(Parametri!D26*1+Parametri!D25)-(Parametri!C8*1)*(Parametri!C26*1+Parametri!C25))/((Parametri!D8*1)*(ROUND((Parametri!D8*1)*(Parametri!D30*1)/(Parametri!D8*1),0)*(Parametri!D34*1)+(ROUND((Parametri!D8*1),0)-ROUND((Parametri!D8*1)*(Parametri!D30*1),0))*(Parametri!D35))-(Parametri!C8*1)*(ROUND((Parametri!C8*1)*(Parametri!C30*1.2)/(Parametri!C8*1),0)*(Parametri!C34*1)+(ROUND((Parametri!C8*1),0)-ROUND((Parametri!C8*1)*(Parametri!C30*1.2),0))*(Parametri!C35))),"N/A") -> 4473.8372 | H9: =IFERROR(((Parametri!D8*1)*(Parametri!D26*1+Parametri!D25)-(Parametri!C8*1)*(Parametri!C26*1+Parametri!C25))/((Parametri!D8*1)*(ROUND((Parametri!D8*1)*(Parametri!D30*1)/(Parametri!D8*1),0)*(Parametri!D34*1)+(ROUND((Parametri!D8*1),0)-ROUND((Parametri!D8*1)*(Parametri!D30*1),0))*(Parametri!D35))-(Parametri!C8*1)*(ROUND((Parametri!C8*1)*(Parametri!C30*1.4)/(Parametri!C8*1),0)*(Parametri!C34*1)+(ROUND((Parametri!C8*1),0)-ROUND((Parametri!C8*1)*(Parametri!C30*1.4),0))*(Parametri!C35))),"N/A") -> 3005.8594 | I9: =IFERROR(MAX(D9:H9)-MIN(D9:H9),"N/A") -> 43822.373
B10: Tasso risposta CollabCare | C10: =Parametri!D30 -> 0.61 | D10: =IFERROR(((Parametri!D8*1)*(Parametri!D26*1+Parametri!D25)-(Parametri!C8*1)*(Parametri!C26*1+Parametri!C25))/((Parametri!D8*1)*(ROUND((Parametri!D8*1)*(Parametri!D30*0.6)/(Parametri!D8*1),0)*(Parametri!D34*1)+(ROUND((Parametri!D8*1),0)-ROUND((Parametri!D8*1)*(Parametri!D30*0.6),0))*(Parametri!D35))-(Parametri!C8*1)*(ROUND((Parametri!C8*1)*(Parametri!C30*1)/(Parametri!C8*1),0)*(Parametri!C34*1)+(ROUND((Parametri!C8*1),0)-ROUND((Parametri!C8*1)*(Parametri!C30*1),0))*(Parametri!C35))),"N/A") -> 2155.4622 | E10: =IFERROR(((Parametri!D8*1)*(Parametri!D26*1+Parametri!D25)-(Parametri!C8*1)*(Parametri!C26*1+Parametri!C25))/((Parametri!D8*1)*(ROUND((Parametri!D8*1)*(Parametri!D30*0.8)/(Parametri!D8*1),0)*(Parametri!D34*1)+(ROUND((Parametri!D8*1),0)-ROUND((Parametri!D8*1)*(Parametri!D30*0.8),0))*(Parametri!D35))-(Parametri!C8*1)*(ROUND((Parametri!C8*1)*(Parametri!C30*1)/(Parametri!C8*1),0)*(Parametri!C34*1)+(ROUND((Parametri!C8*1),0)-ROUND((Parametri!C8*1)*(Parametri!C30*1),0))*(Parametri!C35))),"N/A") -> 3717.3913 | F10: =IFERROR(((Parametri!D8*1)*(Parametri!D26*1+Parametri!D25)-(Parametri!C8*1)*(Parametri!C26*1+Parametri!C25))/((Parametri!D8*1)*(ROUND((Parametri!D8*1)*(Parametri!D30*1)/(Parametri!D8*1),0)*(Parametri!D34*1)+(ROUND((Parametri!D8*1),0)-ROUND((Parametri!D8*1)*(Parametri!D30*1),0))*(Parametri!D35))-(Parametri!C8*1)*(ROUND((Parametri!C8*1)*(Parametri!C30*1)/(Parametri!C8*1),0)*(Parametri!C34*1)+(ROUND((Parametri!C8*1),0)-ROUND((Parametri!C8*1)*(Parametri!C30*1),0))*(Parametri!C35))),"N/A") -> 8744.3182 | G10: =IFERROR(((Parametri!D8*1)*(Parametri!D26*1+Parametri!D25)-(Parametri!C8*1)*(Parametri!C26*1+Parametri!C25))/((Parametri!D8*1)*(ROUND((Parametri!D8*1)*(Parametri!D30*1.2)/(Parametri!D8*1),0)*(Parametri!D34*1)+(ROUND((Parametri!D8*1),0)-ROUND((Parametri!D8*1)*(Parametri!D30*1.2),0))*(Parametri!D35))-(Parametri!C8*1)*(ROUND((Parametri!C8*1)*(Parametri!C30*1)/(Parametri!C8*1),0)*(Parametri!C34*1)+(ROUND((Parametri!C8*1),0)-ROUND((Parametri!C8*1)*(Parametri!C30*1),0))*(Parametri!C35))),"N/A") -> -13741.071 | H10: =IFERROR(((Parametri!D8*1)*(Parametri!D26*1+Parametri!D25)-(Parametri!C8*1)*(Parametri!C26*1+Parametri!C25))/((Parametri!D8*1)*(ROUND((Parametri!D8*1)*(Parametri!D30*1.4)/(Parametri!D8*1),0)*(Parametri!D34*1)+(ROUND((Parametri!D8*1),0)-ROUND((Parametri!D8*1)*(Parametri!D30*1.4),0))*(Parametri!D35))-(Parametri!C8*1)*(ROUND((Parametri!C8*1)*(Parametri!C30*1)/(Parametri!C8*1),0)*(Parametri!C34*1)+(ROUND((Parametri!C8*1),0)-ROUND((Parametri!C8*1)*(Parametri!C30*1),0))*(Parametri!C35))),"N/A") -> -3735.4369 | I10: =IFERROR(MAX(D10:H10)-MIN(D10:H10),"N/A") -> 22485.39
B11: QALY guadagnati responder iCBT | C11: =Parametri!C34 -> 0.063 | D11: =IFERROR(((Parametri!D8*1)*(Parametri!D26*1+Parametri!D25)-(Parametri!C8*1)*(Parametri!C26*1+Parametri!C25))/((Parametri!D8*1)*(ROUND((Parametri!D8*1)*(Parametri!D30*1)/(Parametri!D8*1),0)*(Parametri!D34*1)+(ROUND((Parametri!D8*1),0)-ROUND((Parametri!D8*1)*(Parametri!D30*1),0))*(Parametri!D35))-(Parametri!C8*1)*(ROUND((Parametri!C8*1)*(Parametri!C30*1)/(Parametri!C8*1),0)*(Parametri!C34*0.6)+(ROUND((Parametri!C8*1),0)-ROUND((Parametri!C8*1)*(Parametri!C30*1),0))*(Parametri!C35))),"N/A") -> 7982.3651 | E11: =IFERROR(((Parametri!D8*1)*(Parametri!D26*1+Parametri!D25)-(Parametri!C8*1)*(Parametri!C26*1+Parametri!C25))/((Parametri!D8*1)*(ROUND((Parametri!D8*1)*(Parametri!D30*1)/(Parametri!D8*1),0)*(Parametri!D34*1)+(ROUND((Parametri!D8*1),0)-ROUND((Parametri!D8*1)*(Parametri!D30*1),0))*(Parametri!D35))-(Parametri!C8*1)*(ROUND((Parametri!C8*1)*(Parametri!C30*1)/(Parametri!C8*1),0)*(Parametri!C34*0.8)+(ROUND((Parametri!C8*1),0)-ROUND((Parametri!C8*1)*(Parametri!C30*1),0))*(Parametri!C35))),"N/A") -> 8345.987 | F11: =IFERROR(((Parametri!D8*1)*(Parametri!D26*1+Parametri!D25)-(Parametri!C8*1)*(Parametri!C26*1+Parametri!C25))/((Parametri!D8*1)*(ROUND((Parametri!D8*1)*(Parametri!D30*1)/(Parametri!D8*1),0)*(Parametri!D34*1)+(ROUND((Parametri!D8*1),0)-ROUND((Parametri!D8*1)*(Parametri!D30*1),0))*(Parametri!D35))-(Parametri!C8*1)*(ROUND((Parametri!C8*1)*(Parametri!C30*1)/(Parametri!C8*1),0)*(Parametri!C34*1)+(ROUND((Parametri!C8*1),0)-ROUND((Parametri!C8*1)*(Parametri!C30*1),0))*(Parametri!C35))),"N/A") -> 8744.3182 | G11: =IFERROR(((Parametri!D8*1)*(Parametri!D26*1+Parametri!D25)-(Parametri!C8*1)*(Parametri!C26*1+Parametri!C25))/((Parametri!D8*1)*(ROUND((Parametri!D8*1)*(Parametri!D30*1)/(Parametri!D8*1),0)*(Parametri!D34*1)+(ROUND((Parametri!D8*1),0)-ROUND((Parametri!D8*1)*(Parametri!D30*1),0))*(Parametri!D35))-(Parametri!C8*1)*(ROUND((Parametri!C8*1)*(Parametri!C30*1)/(Parametri!C8*1),0)*(Parametri!C34*1.2)+(ROUND((Parametri!C8*1),0)-ROUND((Parametri!C8*1)*(Parametri!C30*1),0))*(Parametri!C35))),"N/A") -> 9182.5776 | H11: =IFERROR(((Parametri!D8*1)*(Parametri!D26*1+Parametri!D25)-(Parametri!C8*1)*(Parametri!C26*1+Parametri!C25))/((Parametri!D8*1)*(ROUND((Parametri!D8*1)*(Parametri!D30*1)/(Parametri!D8*1),0)*(Parametri!D34*1)+(ROUND((Parametri!D8*1),0)-ROUND((Parametri!D8*1)*(Parametri!D30*1),0))*(Parametri!D35))-(Parametri!C8*1)*(ROUND((Parametri!C8*1)*(Parametri!C30*1)/(Parametri!C8*1),0)*(Parametri!C34*1.4)+(ROUND((Parametri!C8*1),0)-ROUND((Parametri!C8*1)*(Parametri!C30*1),0))*(Parametri!C35))),"N/A") -> 9667.0854 | I11: =IFERROR(MAX(D11:H11)-MIN(D11:H11),"N/A") -> 1684.7203
B12: QALY guadagnati responder CC | C12: =Parametri!D34 -> 0.075 | D12: =IFERROR(((Parametri!D8*1)*(Parametri!D26*1+Parametri!D25)-(Parametri!C8*1)*(Parametri!C26*1+Parametri!C25))/((Parametri!D8*1)*(ROUND((Parametri!D8*1)*(Parametri!D30*1)/(Parametri!D8*1),0)*(Parametri!D34*0.6)+(ROUND((Parametri!D8*1),0)-ROUND((Parametri!D8*1)*(Parametri!D30*1),0))*(Parametri!D35))-(Parametri!C8*1)*(ROUND((Parametri!C8*1)*(Parametri!C30*1)/(Parametri!C8*1),0)*(Parametri!C34*1)+(ROUND((Parametri!C8*1),0)-ROUND((Parametri!C8*1)*(Parametri!C30*1),0))*(Parametri!C35))),"N/A") -> 9865.3846 | E12: =IFERROR(((Parametri!D8*1)*(Parametri!D26*1+Parametri!D25)-(Parametri!C8*1)*(Parametri!C26*1+Parametri!C25))/((Parametri!D8*1)*(ROUND((Parametri!D8*1)*(Parametri!D30*1)/(Parametri!D8*1),0)*(Parametri!D34*0.8)+(ROUND((Parametri!D8*1),0)-ROUND((Parametri!D8*1)*(Parametri!D30*1),0))*(Parametri!D35))-(Parametri!C8*1)*(ROUND((Parametri!C8*1)*(Parametri!C30*1)/(Parametri!C8*1),0)*(Parametri!C34*1)+(ROUND((Parametri!C8*1),0)-ROUND((Parametri!C8*1)*(Parametri!C30*1),0))*(Parametri!C35))),"N/A") -> 9271.0843 | F12: =IFERROR(((Parametri!D8*1)*(Parametri!D26*1+Parametri!D25)-(Parametri!C8*1)*(Parametri!C26*1+Parametri!C25))/((Parametri!D8*1)*(ROUND((Parametri!D8*1)*(Parametri!D30*1)/(Parametri!D8*1),0)*(Parametri!D34*1)+(ROUND((Parametri!D8*1),0)-ROUND((Parametri!D8*1)*(Parametri!D30*1),0))*(Parametri!D35))-(Parametri!C8*1)*(ROUND((Parametri!C8*1)*(Parametri!C30*1)/(Parametri!C8*1),0)*(Parametri!C34*1)+(ROUND((Parametri!C8*1),0)-ROUND((Parametri!C8*1)*(Parametri!C30*1),0))*(Parametri!C35))),"N/A") -> 8744.3182 | G12: =IFERROR(((Parametri!D8*1)*(Parametri!D26*1+Parametri!D25)-(Parametri!C8*1)*(Parametri!C26*1+Parametri!C25))/((Parametri!D8*1)*(ROUND((Parametri!D8*1)*(Parametri!D30*1)/(Parametri!D8*1),0)*(Parametri!D34*1.2)+(ROUND((Parametri!D8*1),0)-ROUND((Parametri!D8*1)*(Parametri!D30*1),0))*(Parametri!D35))-(Parametri!C8*1)*(ROUND((Parametri!C8*1)*(Parametri!C30*1)/(Parametri!C8*1),0)*(Parametri!C34*1)+(ROUND((Parametri!C8*1),0)-ROUND((Parametri!C8*1)*(Parametri!C30*1),0))*(Parametri!C35))),"N/A") -> 8274.1935 | H12: =IFERROR(((Parametri!D8*1)*(Parametri!D26*1+Parametri!D25)-(Parametri!C8*1)*(Parametri!C26*1+Parametri!C25))/((Parametri!D8*1)*(ROUND((Parametri!D8*1)*(Parametri!D30*1)/(Parametri!D8*1),0)*(Parametri!D34*1.4)+(ROUND((Parametri!D8*1),0)-ROUND((Parametri!D8*1)*(Parametri!D30*1),0))*(Parametri!D35))-(Parametri!C8*1)*(ROUND((Parametri!C8*1)*(Parametri!C30*1)/(Parametri!C8*1),0)*(Parametri!C34*1)+(ROUND((Parametri!C8*1),0)-ROUND((Parametri!C8*1)*(Parametri!C30*1),0))*(Parametri!C35))),"N/A") -> 7852.0408 | I12: =IFERROR(MAX(D12:H12)-MIN(D12:H12),"N/A") -> 2013.3438
B13: Dimensione coorte (N pazienti) | C13: =Parametri!C8 -> 200 | D13: =IFERROR(((Parametri!D8*0.6)*(Parametri!D26*1+Parametri!D25)-(Parametri!C8*0.6)*(Parametri!C26*1+Parametri!C25))/((Parametri!D8*0.6)*(ROUND((Parametri!D8*0.6)*(Parametri!D30*1)/(Parametri!D8*0.6),0)*(Parametri!D34*1)+(ROUND((Parametri!D8*0.6),0)-ROUND((Parametri!D8*0.6)*(Parametri!D30*1),0))*(Parametri!D35))-(Parametri!C8*0.6)*(ROUND((Parametri!C8*0.6)*(Parametri!C30*1)/(Parametri!C8*0.6),0)*(Parametri!C34*1)+(ROUND((Parametri!C8*0.6),0)-ROUND((Parametri!C8*0.6)*(Parametri!C30*1),0))*(Parametri!C35))),"N/A") -> 14250 | E13: =IFERROR(((Parametri!D8*0.8)*(Parametri!D26*1+Parametri!D25)-(Parametri!C8*0.8)*(Parametri!C26*1+Parametri!C25))/((Parametri!D8*0.8)*(ROUND((Parametri!D8*0.8)*(Parametri!D30*1)/(Parametri!D8*0.8),0)*(Parametri!D34*1)+(ROUND((Parametri!D8*0.8),0)-ROUND((Parametri!D8*0.8)*(Parametri!D30*1),0))*(Parametri!D35))-(Parametri!C8*0.8)*(ROUND((Parametri!C8*0.8)*(Parametri!C30*1)/(Parametri!C8*0.8),0)*(Parametri!C34*1)+(ROUND((Parametri!C8*0.8),0)-ROUND((Parametri!C8*0.8)*(Parametri!C30*1),0))*(Parametri!C35))),"N/A") -> 11316.176 | F13: =IFERROR(((Parametri!D8*1)*(Parametri!D26*1+Parametri!D25)-(Parametri!C8*1)*(Parametri!C26*1+Parametri!C25))/((Parametri!D8*1)*(ROUND((Parametri!D8*1)*(Parametri!D30*1)/(Parametri!D8*1),0)*(Parametri!D34*1)+(ROUND((Parametri!D8*1),0)-ROUND((Parametri!D8*1)*(Parametri!D30*1),0))*(Parametri!D35))-(Parametri!C8*1)*(ROUND((Parametri!C8*1)*(Parametri!C30*1)/(Parametri!C8*1),0)*(Parametri!C34*1)+(ROUND((Parametri!C8*1),0)-ROUND((Parametri!C8*1)*(Parametri!C30*1),0))*(Parametri!C35))),"N/A") -> 8744.3182 | G13: =IFERROR(((Parametri!D8*1.2)*(Parametri!D26*1+Parametri!D25)-(Parametri!C8*1.2)*(Parametri!C26*1+Parametri!C25))/((Parametri!D8*1.2)*(ROUND((Parametri!D8*1.2)*(Parametri!D30*1)/(Parametri!D8*1.2),0)*(Parametri!D34*1)+(ROUND((Parametri!D8*1.2),0)-ROUND((Parametri!D8*1.2)*(Parametri!D30*1),0))*(Parametri!D35))-(Parametri!C8*1.2)*(ROUND((Parametri!C8*1.2)*(Parametri!C30*1)/(Parametri!C8*1.2),0)*(Parametri!C34*1)+(ROUND((Parametri!C8*1.2),0)-ROUND((Parametri!C8*1.2)*(Parametri!C30*1),0))*(Parametri!C35))),"N/A") -> 7125 | H13: =IFERROR(((Parametri!D8*1.4)*(Parametri!D26*1+Parametri!D25)-(Parametri!C8*1.4)*(Parametri!C26*1+Parametri!C25))/((Parametri!D8*1.4)*(ROUND((Parametri!D8*1.4)*(Parametri!D30*1)/(Parametri!D8*1.4),0)*(Parametri!D34*1)+(ROUND((Parametri!D8*1.4),0)-ROUND((Parametri!D8*1.4)*(Parametri!D30*1),0))*(Parametri!D35))-(Parametri!C8*1.4)*(ROUND((Parametri!C8*1.4)*(Parametri!C30*1)/(Parametri!C8*1.4),0)*(Parametri!C34*1)+(ROUND((Parametri!C8*1.4),0)-ROUND((Parametri!C8*1.4)*(Parametri!C30*1),0))*(Parametri!C35))),"N/A") -> 6307.377 | I13: =IFERROR(MAX(D13:H13)-MIN(D13:H13),"N/A") -> 7942.623
B15: B | SENSIBILITÀ BI-VARIATA – Costo/paz iCBT (riga) × Tasso Risposta iCBT (colonna)
B16: Valori = ICER (€/QALY, Anno 1). Verde = ICER < €30.000/QALY (CC cost-effective); Rosso = ICER > €30.000/QALY. Giallo = zona critica ±10%.
B17: Costo/paz iCBT → Risposta iCBT ↓ | C17: 0.36 | D17: 0.42 | E17: 0.48 | F17: 0.52 | G17: 0.58 | H17: 0.64
B18: 80 | C18: =IFERROR((Parametri!D8*(Parametri!D26+Parametri!D25)-Parametri!C8*(80+Parametri!C25))/(Parametri!D8*(ROUND(Parametri!D8*Parametri!D30,0)/Parametri!D8*Parametri!D34+(1-ROUND(Parametri!D8*Parametri!D30,0)/Parametri!D8)*Parametri!D35)-Parametri!C8*(0.36*Parametri!C34+(1-0.36)*Parametri!C35)),"N/A") -> 119199.02 | D18: =IFERROR((Parametri!D8*(Parametri!D26+Parametri!D25)-Parametri!C8*(80+Parametri!C25))/(Parametri!D8*(ROUND(Parametri!D8*Parametri!D30,0)/Parametri!D8*Parametri!D34+(1-ROUND(Parametri!D8*Parametri!D30,0)/Parametri!D8)*Parametri!D35)-Parametri!C8*(0.42*Parametri!C34+(1-0.42)*Parametri!C35)),"N/A") -> 138049.1 | E18: =IFERROR((Parametri!D8*(Parametri!D26+Parametri!D25)-Parametri!C8*(80+Parametri!C25))/(Parametri!D8*(ROUND(Parametri!D8*Parametri!D30,0)/Parametri!D8*Parametri!D34+(1-ROUND(Parametri!D8*Parametri!D30,0)/Parametri!D8)*Parametri!D35)-Parametri!C8*(0.48*Parametri!C34+(1-0.48)*Parametri!C35)),"N/A") -> 163980.97 | F18: =IFERROR((Parametri!D8*(Parametri!D26+Parametri!D25)-Parametri!C8*(80+Parametri!C25))/(Parametri!D8*(ROUND(Parametri!D8*Parametri!D30,0)/Parametri!D8*Parametri!D34+(1-ROUND(Parametri!D8*Parametri!D30,0)/Parametri!D8)*Parametri!D35)-Parametri!C8*(0.52*Parametri!C34+(1-0.52)*Parametri!C35)),"N/A") -> 187456.14 | G18: =IFERROR((Parametri!D8*(Parametri!D26+Parametri!D25)-Parametri!C8*(80+Parametri!C25))/(Parametri!D8*(ROUND(Parametri!D8*Parametri!D30,0)/Parametri!D8*Parametri!D34+(1-ROUND(Parametri!D8*Parametri!D30,0)/Parametri!D8)*Parametri!D35)-Parametri!C8*(0.58*Parametri!C34+(1-0.58)*Parametri!C35)),"N/A") -> 238717.61 | H18: =IFERROR((Parametri!D8*(Parametri!D26+Parametri!D25)-Parametri!C8*(80+Parametri!C25))/(Parametri!D8*(ROUND(Parametri!D8*Parametri!D30,0)/Parametri!D8*Parametri!D34+(1-ROUND(Parametri!D8*Parametri!D30,0)/Parametri!D8)*Parametri!D35)-Parametri!C8*(0.64*Parametri!C34+(1-0.64)*Parametri!C35)),"N/A") -> 328567.04
B19: 120 | C19: =IFERROR((Parametri!D8*(Parametri!D26+Parametri!D25)-Parametri!C8*(120+Parametri!C25))/(Parametri!D8*(ROUND(Parametri!D8*Parametri!D30,0)/Parametri!D8*Parametri!D34+(1-ROUND(Parametri!D8*Parametri!D30,0)/Parametri!D8)*Parametri!D35)-Parametri!C8*(0.36*Parametri!C34+(1-0.36)*Parametri!C35)),"N/A") -> 117414.1 | D19: =IFERROR((Parametri!D8*(Parametri!D26+Parametri!D25)-Parametri!C8*(120+Parametri!C25))/(Parametri!D8*(ROUND(Parametri!D8*Parametri!D30,0)/Parametri!D8*Parametri!D34+(1-ROUND(Parametri!D8*Parametri!D30,0)/Parametri!D8)*Parametri!D35)-Parametri!C8*(0.42*Parametri!C34+(1-0.42)*Parametri!C35)),"N/A") -> 135981.91 | E19: =IFERROR((Parametri!D8*(Parametri!D26+Parametri!D25)-Parametri!C8*(120+Parametri!C25))/(Parametri!D8*(ROUND(Parametri!D8*Parametri!D30,0)/Parametri!D8*Parametri!D34+(1-ROUND(Parametri!D8*Parametri!D30,0)/Parametri!D8)*Parametri!D35)-Parametri!C8*(0.48*Parametri!C34+(1-0.48)*Parametri!C35)),"N/A") -> 161525.48 | F19: =IFERROR((Parametri!D8*(Parametri!D26+Parametri!D25)-Parametri!C8*(120+Parametri!C25))/(Parametri!D8*(ROUND(Parametri!D8*Parametri!D30,0)/Parametri!D8*Parametri!D34+(1-ROUND(Parametri!D8*Parametri!D30,0)/Parametri!D8)*Parametri!D35)-Parametri!C8*(0.52*Parametri!C34+(1-0.52)*Parametri!C35)),"N/A") -> 184649.12 | G19: =IFERROR((Parametri!D8*(Parametri!D26+Parametri!D25)-Parametri!C8*(120+Parametri!C25))/(Parametri!D8*(ROUND(Parametri!D8*Parametri!D30,0)/Parametri!D8*Parametri!D34+(1-ROUND(Parametri!D8*Parametri!D30,0)/Parametri!D8)*Parametri!D35)-Parametri!C8*(0.58*Parametri!C34+(1-0.58)*Parametri!C35)),"N/A") -> 235142.98 | H19: =IFERROR((Parametri!D8*(Parametri!D26+Parametri!D25)-Parametri!C8*(120+Parametri!C25))/(Parametri!D8*(ROUND(Parametri!D8*Parametri!D30,0)/Parametri!D8*Parametri!D34+(1-ROUND(Parametri!D8*Parametri!D30,0)/Parametri!D8)*Parametri!D35)-Parametri!C8*(0.64*Parametri!C34+(1-0.64)*Parametri!C35)),"N/A") -> 323646.99
B20: 180 | C20: =IFERROR((Parametri!D8*(Parametri!D26+Parametri!D25)-Parametri!C8*(180+Parametri!C25))/(Parametri!D8*(ROUND(Parametri!D8*Parametri!D30,0)/Parametri!D8*Parametri!D34+(1-ROUND(Parametri!D8*Parametri!D30,0)/Parametri!D8)*Parametri!D35)-Parametri!C8*(0.36*Parametri!C34+(1-0.36)*Parametri!C35)),"N/A") -> 114736.72 | D20: =IFERROR((Parametri!D8*(Parametri!D26+Parametri!D25)-Parametri!C8*(180+Parametri!C25))/(Parametri!D8*(ROUND(Parametri!D8*Parametri!D30,0)/Parametri!D8*Parametri!D34+(1-ROUND(Parametri!D8*Parametri!D30,0)/Parametri!D8)*Parametri!D35)-Parametri!C8*(0.42*Parametri!C34+(1-0.42)*Parametri!C35)),"N/A") -> 132881.14 | E20: =IFERROR((Parametri!D8*(Parametri!D26+Parametri!D25)-Parametri!C8*(180+Parametri!C25))/(Parametri!D8*(ROUND(Parametri!D8*Parametri!D30,0)/Parametri!D8*Parametri!D34+(1-ROUND(Parametri!D8*Parametri!D30,0)/Parametri!D8)*Parametri!D35)-Parametri!C8*(0.48*Parametri!C34+(1-0.48)*Parametri!C35)),"N/A") -> 157842.23 | F20: =IFERROR((Parametri!D8*(Parametri!D26+Parametri!D25)-Parametri!C8*(180+Parametri!C25))/(Parametri!D8*(ROUND(Parametri!D8*Parametri!D30,0)/Parametri!D8*Parametri!D34+(1-ROUND(Parametri!D8*Parametri!D30,0)/Parametri!D8)*Parametri!D35)-Parametri!C8*(0.52*Parametri!C34+(1-0.52)*Parametri!C35)),"N/A") -> 180438.6 | G20: =IFERROR((Parametri!D8*(Parametri!D26+Parametri!D25)-Parametri!C8*(180+Parametri!C25))/(Parametri!D8*(ROUND(Parametri!D8*Parametri!D30,0)/Parametri!D8*Parametri!D34+(1-ROUND(Parametri!D8*Parametri!D30,0)/Parametri!D8)*Parametri!D35)-Parametri!C8*(0.58*Parametri!C34+(1-0.58)*Parametri!C35)),"N/A") -> 229781.05 | H20: =IFERROR((Parametri!D8*(Parametri!D26+Parametri!D25)-Parametri!C8*(180+Parametri!C25))/(Parametri!D8*(ROUND(Parametri!D8*Parametri!D30,0)/Parametri!D8*Parametri!D34+(1-ROUND(Parametri!D8*Parametri!D30,0)/Parametri!D8)*Parametri!D35)-Parametri!C8*(0.64*Parametri!C34+(1-0.64)*Parametri!C35)),"N/A") -> 316266.91
B21: 240 | C21: =IFERROR((Parametri!D8*(Parametri!D26+Parametri!D25)-Parametri!C8*(240+Parametri!C25))/(Parametri!D8*(ROUND(Parametri!D8*Parametri!D30,0)/Parametri!D8*Parametri!D34+(1-ROUND(Parametri!D8*Parametri!D30,0)/Parametri!D8)*Parametri!D35)-Parametri!C8*(0.36*Parametri!C34+(1-0.36)*Parametri!C35)),"N/A") -> 112059.35 | D21: =IFERROR((Parametri!D8*(Parametri!D26+Parametri!D25)-Parametri!C8*(240+Parametri!C25))/(Parametri!D8*(ROUND(Parametri!D8*Parametri!D30,0)/Parametri!D8*Parametri!D34+(1-ROUND(Parametri!D8*Parametri!D30,0)/Parametri!D8)*Parametri!D35)-Parametri!C8*(0.42*Parametri!C34+(1-0.42)*Parametri!C35)),"N/A") -> 129780.36 | E21: =IFERROR((Parametri!D8*(Parametri!D26+Parametri!D25)-Parametri!C8*(240+Parametri!C25))/(Parametri!D8*(ROUND(Parametri!D8*Parametri!D30,0)/Parametri!D8*Parametri!D34+(1-ROUND(Parametri!D8*Parametri!D30,0)/Parametri!D8)*Parametri!D35)-Parametri!C8*(0.48*Parametri!C34+(1-0.48)*Parametri!C35)),"N/A") -> 154158.99 | F21: =IFERROR((Parametri!D8*(Parametri!D26+Parametri!D25)-Parametri!C8*(240+Parametri!C25))/(Parametri!D8*(ROUND(Parametri!D8*Parametri!D30,0)/Parametri!D8*Parametri!D34+(1-ROUND(Parametri!D8*Parametri!D30,0)/Parametri!D8)*Parametri!D35)-Parametri!C8*(0.52*Parametri!C34+(1-0.52)*Parametri!C35)),"N/A") -> 176228.07 | G21: =IFERROR((Parametri!D8*(Parametri!D26+Parametri!D25)-Parametri!C8*(240+Parametri!C25))/(Parametri!D8*(ROUND(Parametri!D8*Parametri!D30,0)/Parametri!D8*Parametri!D34+(1-ROUND(Parametri!D8*Parametri!D30,0)/Parametri!D8)*Parametri!D35)-Parametri!C8*(0.58*Parametri!C34+(1-0.58)*Parametri!C35)),"N/A") -> 224419.12 | H21: =IFERROR((Parametri!D8*(Parametri!D26+Parametri!D25)-Parametri!C8*(240+Parametri!C25))/(Parametri!D8*(ROUND(Parametri!D8*Parametri!D30,0)/Parametri!D8*Parametri!D34+(1-ROUND(Parametri!D8*Parametri!D30,0)/Parametri!D8)*Parametri!D35)-Parametri!C8*(0.64*Parametri!C34+(1-0.64)*Parametri!C35)),"N/A") -> 308886.84
B22: 320 | C22: =IFERROR((Parametri!D8*(Parametri!D26+Parametri!D25)-Parametri!C8*(320+Parametri!C25))/(Parametri!D8*(ROUND(Parametri!D8*Parametri!D30,0)/Parametri!D8*Parametri!D34+(1-ROUND(Parametri!D8*Parametri!D30,0)/Parametri!D8)*Parametri!D35)-Parametri!C8*(0.36*Parametri!C34+(1-0.36)*Parametri!C35)),"N/A") -> 108489.51 | D22: =IFERROR((Parametri!D8*(Parametri!D26+Parametri!D25)-Parametri!C8*(320+Parametri!C25))/(Parametri!D8*(ROUND(Parametri!D8*Parametri!D30,0)/Parametri!D8*Parametri!D34+(1-ROUND(Parametri!D8*Parametri!D30,0)/Parametri!D8)*Parametri!D35)-Parametri!C8*(0.42*Parametri!C34+(1-0.42)*Parametri!C35)),"N/A") -> 125645.99 | E22: =IFERROR((Parametri!D8*(Parametri!D26+Parametri!D25)-Parametri!C8*(320+Parametri!C25))/(Parametri!D8*(ROUND(Parametri!D8*Parametri!D30,0)/Parametri!D8*Parametri!D34+(1-ROUND(Parametri!D8*Parametri!D30,0)/Parametri!D8)*Parametri!D35)-Parametri!C8*(0.48*Parametri!C34+(1-0.48)*Parametri!C35)),"N/A") -> 149248 | F22: =IFERROR((Parametri!D8*(Parametri!D26+Parametri!D25)-Parametri!C8*(320+Parametri!C25))/(Parametri!D8*(ROUND(Parametri!D8*Parametri!D30,0)/Parametri!D8*Parametri!D34+(1-ROUND(Parametri!D8*Parametri!D30,0)/Parametri!D8)*Parametri!D35)-Parametri!C8*(0.52*Parametri!C34+(1-0.52)*Parametri!C35)),"N/A") -> 170614.04 | G22: =IFERROR((Parametri!D8*(Parametri!D26+Parametri!D25)-Parametri!C8*(320+Parametri!C25))/(Parametri!D8*(ROUND(Parametri!D8*Parametri!D30,0)/Parametri!D8*Parametri!D34+(1-ROUND(Parametri!D8*Parametri!D30,0)/Parametri!D8)*Parametri!D35)-Parametri!C8*(0.58*Parametri!C34+(1-0.58)*Parametri!C35)),"N/A") -> 217269.88 | H22: =IFERROR((Parametri!D8*(Parametri!D26+Parametri!D25)-Parametri!C8*(320+Parametri!C25))/(Parametri!D8*(ROUND(Parametri!D8*Parametri!D30,0)/Parametri!D8*Parametri!D34+(1-ROUND(Parametri!D8*Parametri!D30,0)/Parametri!D8)*Parametri!D35)-Parametri!C8*(0.64*Parametri!C34+(1-0.64)*Parametri!C35)),"N/A") -> 299046.74
B23: 400 | C23: =IFERROR((Parametri!D8*(Parametri!D26+Parametri!D25)-Parametri!C8*(400+Parametri!C25))/(Parametri!D8*(ROUND(Parametri!D8*Parametri!D30,0)/Parametri!D8*Parametri!D34+(1-ROUND(Parametri!D8*Parametri!D30,0)/Parametri!D8)*Parametri!D35)-Parametri!C8*(0.36*Parametri!C34+(1-0.36)*Parametri!C35)),"N/A") -> 104919.68 | D23: =IFERROR((Parametri!D8*(Parametri!D26+Parametri!D25)-Parametri!C8*(400+Parametri!C25))/(Parametri!D8*(ROUND(Parametri!D8*Parametri!D30,0)/Parametri!D8*Parametri!D34+(1-ROUND(Parametri!D8*Parametri!D30,0)/Parametri!D8)*Parametri!D35)-Parametri!C8*(0.42*Parametri!C34+(1-0.42)*Parametri!C35)),"N/A") -> 121511.63 | E23: =IFERROR((Parametri!D8*(Parametri!D26+Parametri!D25)-Parametri!C8*(400+Parametri!C25))/(Parametri!D8*(ROUND(Parametri!D8*Parametri!D30,0)/Parametri!D8*Parametri!D34+(1-ROUND(Parametri!D8*Parametri!D30,0)/Parametri!D8)*Parametri!D35)-Parametri!C8*(0.48*Parametri!C34+(1-0.48)*Parametri!C35)),"N/A") -> 144337.02 | F23: =IFERROR((Parametri!D8*(Parametri!D26+Parametri!D25)-Parametri!C8*(400+Parametri!C25))/(Parametri!D8*(ROUND(Parametri!D8*Parametri!D30,0)/Parametri!D8*Parametri!D34+(1-ROUND(Parametri!D8*Parametri!D30,0)/Parametri!D8)*Parametri!D35)-Parametri!C8*(0.52*Parametri!C34+(1-0.52)*Parametri!C35)),"N/A") -> 165000 | G23: =IFERROR((Parametri!D8*(Parametri!D26+Parametri!D25)-Parametri!C8*(400+Parametri!C25))/(Parametri!D8*(ROUND(Parametri!D8*Parametri!D30,0)/Parametri!D8*Parametri!D34+(1-ROUND(Parametri!D8*Parametri!D30,0)/Parametri!D8)*Parametri!D35)-Parametri!C8*(0.58*Parametri!C34+(1-0.58)*Parametri!C35)),"N/A") -> 210120.64 | H23: =IFERROR((Parametri!D8*(Parametri!D26+Parametri!D25)-Parametri!C8*(400+Parametri!C25))/(Parametri!D8*(ROUND(Parametri!D8*Parametri!D30,0)/Parametri!D8*Parametri!D34+(1-ROUND(Parametri!D8*Parametri!D30,0)/Parametri!D8)*Parametri!D35)-Parametri!C8*(0.64*Parametri!C34+(1-0.64)*Parametri!C35)),"N/A") -> 289206.64
B24: 500 | C24: =IFERROR((Parametri!D8*(Parametri!D26+Parametri!D25)-Parametri!C8*(500+Parametri!C25))/(Parametri!D8*(ROUND(Parametri!D8*Parametri!D30,0)/Parametri!D8*Parametri!D34+(1-ROUND(Parametri!D8*Parametri!D30,0)/Parametri!D8)*Parametri!D35)-Parametri!C8*(0.36*Parametri!C34+(1-0.36)*Parametri!C35)),"N/A") -> 100457.39 | D24: =IFERROR((Parametri!D8*(Parametri!D26+Parametri!D25)-Parametri!C8*(500+Parametri!C25))/(Parametri!D8*(ROUND(Parametri!D8*Parametri!D30,0)/Parametri!D8*Parametri!D34+(1-ROUND(Parametri!D8*Parametri!D30,0)/Parametri!D8)*Parametri!D35)-Parametri!C8*(0.42*Parametri!C34+(1-0.42)*Parametri!C35)),"N/A") -> 116343.67 | E24: =IFERROR((Parametri!D8*(Parametri!D26+Parametri!D25)-Parametri!C8*(500+Parametri!C25))/(Parametri!D8*(ROUND(Parametri!D8*Parametri!D30,0)/Parametri!D8*Parametri!D34+(1-ROUND(Parametri!D8*Parametri!D30,0)/Parametri!D8)*Parametri!D35)-Parametri!C8*(0.48*Parametri!C34+(1-0.48)*Parametri!C35)),"N/A") -> 138198.28 | F24: =IFERROR((Parametri!D8*(Parametri!D26+Parametri!D25)-Parametri!C8*(500+Parametri!C25))/(Parametri!D8*(ROUND(Parametri!D8*Parametri!D30,0)/Parametri!D8*Parametri!D34+(1-ROUND(Parametri!D8*Parametri!D30,0)/Parametri!D8)*Parametri!D35)-Parametri!C8*(0.52*Parametri!C34+(1-0.52)*Parametri!C35)),"N/A") -> 157982.46 | G24: =IFERROR((Parametri!D8*(Parametri!D26+Parametri!D25)-Parametri!C8*(500+Parametri!C25))/(Parametri!D8*(ROUND(Parametri!D8*Parametri!D30,0)/Parametri!D8*Parametri!D34+(1-ROUND(Parametri!D8*Parametri!D30,0)/Parametri!D8)*Parametri!D35)-Parametri!C8*(0.58*Parametri!C34+(1-0.58)*Parametri!C35)),"N/A") -> 201184.09 | H24: =IFERROR((Parametri!D8*(Parametri!D26+Parametri!D25)-Parametri!C8*(500+Parametri!C25))/(Parametri!D8*(ROUND(Parametri!D8*Parametri!D30,0)/Parametri!D8*Parametri!D34+(1-ROUND(Parametri!D8*Parametri!D30,0)/Parametri!D8)*Parametri!D35)-Parametri!C8*(0.64*Parametri!C34+(1-0.64)*Parametri!C35)),"N/A") -> 276906.52
B26: C | SENSIBILITÀ ROI 36 MESI – iCBT al variare di N pazienti e Costo Piattaforma
B27: Tabella: N pazienti (righe) × Costo piattaforma/paz (colonne). Valori = ROI% iCBT a 36 mesi.
B28: N paz → Costo piatt ↓ | C28: 60 | D28: 90 | E28: 120 | F28: 150 | G28: 200 | H28: 250
B29: 50 | C29: =IFERROR((ROUND(50*Parametri!C30,0)*Parametri!C34*Parametri!C43*(1+Parametri!C38+Parametri!C39)+ROUND(50*Parametri!C30,0)*Parametri!C47*Parametri!C46*Parametri!C48*(1+(1+Parametri!C45)+(1+Parametri!C45)^2)-(50*((60+Parametri!C26-120)*1.15+Parametri!C25)+50*(Parametri!C26-120+60)*1.15*(1+Parametri!C45)+50*(Parametri!C26-120+60)*1.15*(1+Parametri!C45)^2))/(50*((60+Parametri!C26-120)*1.15+Parametri!C25)+50*(Parametri!C26-120+60)*1.15*(1+Parametri!C45)+50*(Parametri!C26-120+60)*1.15*(1+Parametri!C45)^2),"N/A") -> 4.7965281 | D29: =IFERROR((ROUND(50*Parametri!C30,0)*Parametri!C34*Parametri!C43*(1+Parametri!C38+Parametri!C39)+ROUND(50*Parametri!C30,0)*Parametri!C47*Parametri!C46*Parametri!C48*(1+(1+Parametri!C45)+(1+Parametri!C45)^2)-(50*((90+Parametri!C26-120)*1.15+Parametri!C25)+50*(Parametri!C26-120+90)*1.15*(1+Parametri!C45)+50*(Parametri!C26-120+90)*1.15*(1+Parametri!C45)^2))/(50*((90+Parametri!C26-120)*1.15+Parametri!C25)+50*(Parametri!C26-120+90)*1.15*(1+Parametri!C45)+50*(Parametri!C26-120+90)*1.15*(1+Parametri!C45)^2),"N/A") -> 4.3837012 | E29: =IFERROR((ROUND(50*Parametri!C30,0)*Parametri!C34*Parametri!C43*(1+Parametri!C38+Parametri!C39)+ROUND(50*Parametri!C30,0)*Parametri!C47*Parametri!C46*Parametri!C48*(1+(1+Parametri!C45)+(1+Parametri!C45)^2)-(50*((120+Parametri!C26-120)*1.15+Parametri!C25)+50*(Parametri!C26-120+120)*1.15*(1+Parametri!C45)+50*(Parametri!C26-120+120)*1.15*(1+Parametri!C45)^2))/(50*((120+Parametri!C26-120)*1.15+Parametri!C25)+50*(Parametri!C26-120+120)*1.15*(1+Parametri!C45)+50*(Parametri!C26-120+120)*1.15*(1+Parametri!C45)^2),"N/A") -> 4.0257676 | F29: =IFERROR((ROUND(50*Parametri!C30,0)*Parametri!C34*Parametri!C43*(1+Parametri!C38+Parametri!C39)+ROUND(50*Parametri!C30,0)*Parametri!C47*Parametri!C46*Parametri!C48*(1+(1+Parametri!C45)+(1+Parametri!C45)^2)-(50*((150+Parametri!C26-120)*1.15+Parametri!C25)+50*(Parametri!C26-120+150)*1.15*(1+Parametri!C45)+50*(Parametri!C26-120+150)*1.15*(1+Parametri!C45)^2))/(50*((150+Parametri!C26-120)*1.15+Parametri!C25)+50*(Parametri!C26-120+150)*1.15*(1+Parametri!C45)+50*(Parametri!C26-120+150)*1.15*(1+Parametri!C45)^2),"N/A") -> 3.7124612 | G29: =IFERROR((ROUND(50*Parametri!C30,0)*Parametri!C34*Parametri!C43*(1+Parametri!C38+Parametri!C39)+ROUND(50*Parametri!C30,0)*Parametri!C47*Parametri!C46*Parametri!C48*(1+(1+Parametri!C45)+(1+Parametri!C45)^2)-(50*((200+Parametri!C26-120)*1.15+Parametri!C25)+50*(Parametri!C26-120+200)*1.15*(1+Parametri!C45)+50*(Parametri!C26-120+200)*1.15*(1+Parametri!C45)^2))/(50*((200+Parametri!C26-120)*1.15+Parametri!C25)+50*(Parametri!C26-120+200)*1.15*(1+Parametri!C45)+50*(Parametri!C26-120+200)*1.15*(1+Parametri!C45)^2),"N/A") -> 3.2689202 | H29: =IFERROR((ROUND(50*Parametri!C30,0)*Parametri!C34*Parametri!C43*(1+Parametri!C38+Parametri!C39)+ROUND(50*Parametri!C30,0)*Parametri!C47*Parametri!C46*Parametri!C48*(1+(1+Parametri!C45)+(1+Parametri!C45)^2)-(50*((250+Parametri!C26-120)*1.15+Parametri!C25)+50*(Parametri!C26-120+250)*1.15*(1+Parametri!C45)+50*(Parametri!C26-120+250)*1.15*(1+Parametri!C45)^2))/(50*((250+Parametri!C26-120)*1.15+Parametri!C25)+50*(Parametri!C26-120+250)*1.15*(1+Parametri!C45)+50*(Parametri!C26-120+250)*1.15*(1+Parametri!C45)^2),"N/A") -> 2.9016898
B30: 100 | C30: =IFERROR((ROUND(100*Parametri!C30,0)*Parametri!C34*Parametri!C43*(1+Parametri!C38+Parametri!C39)+ROUND(100*Parametri!C30,0)*Parametri!C47*Parametri!C46*Parametri!C48*(1+(1+Parametri!C45)+(1+Parametri!C45)^2)-(100*((60+Parametri!C26-120)*1.15+Parametri!C25)+100*(Parametri!C26-120+60)*1.15*(1+Parametri!C45)+100*(Parametri!C26-120+60)*1.15*(1+Parametri!C45)^2))/(100*((60+Parametri!C26-120)*1.15+Parametri!C25)+100*(Parametri!C26-120+60)*1.15*(1+Parametri!C45)+100*(Parametri!C26-120+60)*1.15*(1+Parametri!C45)^2),"N/A") -> 4.7965281 | D30: =IFERROR((ROUND(100*Parametri!C30,0)*Parametri!C34*Parametri!C43*(1+Parametri!C38+Parametri!C39)+ROUND(100*Parametri!C30,0)*Parametri!C47*Parametri!C46*Parametri!C48*(1+(1+Parametri!C45)+(1+Parametri!C45)^2)-(100*((90+Parametri!C26-120)*1.15+Parametri!C25)+100*(Parametri!C26-120+90)*1.15*(1+Parametri!C45)+100*(Parametri!C26-120+90)*1.15*(1+Parametri!C45)^2))/(100*((90+Parametri!C26-120)*1.15+Parametri!C25)+100*(Parametri!C26-120+90)*1.15*(1+Parametri!C45)+100*(Parametri!C26-120+90)*1.15*(1+Parametri!C45)^2),"N/A") -> 4.3837012 | E30: =IFERROR((ROUND(100*Parametri!C30,0)*Parametri!C34*Parametri!C43*(1+Parametri!C38+Parametri!C39)+ROUND(100*Parametri!C30,0)*Parametri!C47*Parametri!C46*Parametri!C48*(1+(1+Parametri!C45)+(1+Parametri!C45)^2)-(100*((120+Parametri!C26-120)*1.15+Parametri!C25)+100*(Parametri!C26-120+120)*1.15*(1+Parametri!C45)+100*(Parametri!C26-120+120)*1.15*(1+Parametri!C45)^2))/(100*((120+Parametri!C26-120)*1.15+Parametri!C25)+100*(Parametri!C26-120+120)*1.15*(1+Parametri!C45)+100*(Parametri!C26-120+120)*1.15*(1+Parametri!C45)^2),"N/A") -> 4.0257676 | F30: =IFERROR((ROUND(100*Parametri!C30,0)*Parametri!C34*Parametri!C43*(1+Parametri!C38+Parametri!C39)+ROUND(100*Parametri!C30,0)*Parametri!C47*Parametri!C46*Parametri!C48*(1+(1+Parametri!C45)+(1+Parametri!C45)^2)-(100*((150+Parametri!C26-120)*1.15+Parametri!C25)+100*(Parametri!C26-120+150)*1.15*(1+Parametri!C45)+100*(Parametri!C26-120+150)*1.15*(1+Parametri!C45)^2))/(100*((150+Parametri!C26-120)*1.15+Parametri!C25)+100*(Parametri!C26-120+150)*1.15*(1+Parametri!C45)+100*(Parametri!C26-120+150)*1.15*(1+Parametri!C45)^2),"N/A") -> 3.7124612 | G30: =IFERROR((ROUND(100*Parametri!C30,0)*Parametri!C34*Parametri!C43*(1+Parametri!C38+Parametri!C39)+ROUND(100*Parametri!C30,0)*Parametri!C47*Parametri!C46*Parametri!C48*(1+(1+Parametri!C45)+(1+Parametri!C45)^2)-(100*((200+Parametri!C26-120)*1.15+Parametri!C25)+100*(Parametri!C26-120+200)*1.15*(1+Parametri!C45)+100*(Parametri!C26-120+200)*1.15*(1+Parametri!C45)^2))/(100*((200+Parametri!C26-120)*1.15+Parametri!C25)+100*(Parametri!C26-120+200)*1.15*(1+Parametri!C45)+100*(Parametri!C26-120+200)*1.15*(1+Parametri!C45)^2),"N/A") -> 3.2689202 | H30: =IFERROR((ROUND(100*Parametri!C30,0)*Parametri!C34*Parametri!C43*(1+Parametri!C38+Parametri!C39)+ROUND(100*Parametri!C30,0)*Parametri!C47*Parametri!C46*Parametri!C48*(1+(1+Parametri!C45)+(1+Parametri!C45)^2)-(100*((250+Parametri!C26-120)*1.15+Parametri!C25)+100*(Parametri!C26-120+250)*1.15*(1+Parametri!C45)+100*(Parametri!C26-120+250)*1.15*(1+Parametri!C45)^2))/(100*((250+Parametri!C26-120)*1.15+Parametri!C25)+100*(Parametri!C26-120+250)*1.15*(1+Parametri!C45)+100*(Parametri!C26-120+250)*1.15*(1+Parametri!C45)^2),"N/A") -> 2.9016898
